Workbook

Sheet первоначальная
A1: ID | B1: Сколько вам лет? | C1: Сфера деятельности | D1: Слышали ли вы когда-нибудь о нейросетях? | E1: Откуда узнали о нейросетях? | F1: Пользовались ли вы когда-нибудь нейросетями? | G1: Как часто вы пользуетесь нейросетями? | H1: Какими именно нейросетями вы пользуетесь?? / ChatGPT | I1: Какими именно нейросетями вы пользуетесь?? / DeepSeek | J1: Какими именно нейросетями вы пользуетесь?? / Grok | K1: Какими именно нейросетями вы пользуетесь?? / YandexGPT | L1: Какими именно нейросетями вы пользуетесь?? / GigaChat | M1: Какими именно нейросетями вы пользуетесь?? / Генераторы изображений (Midjourney, Kandinsky) | N1: Какими именно нейросетями вы пользуетесь?? / Генераторы видео (Sora и др.) | O1: Какими именно нейросетями вы пользуетесь?? / Нейросети для обработки фото/видео | P1: Какими именно нейросетями вы пользуетесь?? / Другие | Q1: Для каких задач вы используете нейросети? / Поиск информации, обучение | R1: Для каких задач вы используете нейросети? / Написание текстов | S1: Для каких задач вы используете нейросети? / Создание изображений, артов | T1: Для каких задач вы используете нейросети? / Создание видео | U1: Для каких задач вы используете нейросети? / Программирование | V1: Для каких задач вы используете нейросети? / Работа | W1: Для каких задач вы используете нейросети? / Развлечения | X1: Для каких задач вы используете нейросети? / Пока не использую | Y1: Как вы считаете, как нейросети влияют на вашу эффективность? / | Z1: Готовы ли вы платить за более продвинутую версию нейросети? | AA1: Насколько вы доверяете информации нейросетей? / 1-5 | AB1: Как использование нейросетей изменится в будущем? | AC1: Как вы считаете, какие основные риски ИИ? / Потеря работ | AD1: Как вы считаете, какие основные риски ИИ? / Фейковая информация | AE1: Как вы считаете, какие основные риски ИИ? / Потеря креативности | AF1: Как вы считаете, какие основные риски ИИ? / Контроль над людьми | AG1: Как вы считаете, какие основные риски ИИ? / Развитие лени | AH1: Как вы считаете, какие основные риски ИИ? / Рисков не вижу | AI1: Как вы считаете, как ИИ влияет на рынок труда? | AJ1: Насколько вы готовы осваивать новые навыки в связи с развитием ИИ? / 1-5 | AK1: Насколько вы в целом оптимистично или пессимистично относитесь к стремительному развитию искусственного интеллекта? / 1 (Чрезвычайно пессимистично) — 10 (Чрезвычайно оптимистично). | AL1: В каких сферах, по-вашему, нейросети принесут наибольшую пользу человечеству в ближайшие 10 лет? (Выберите не более 3-х вариантов) / Медицина (диагностика, разработка лекарств) | AM1: В каких сферах, по-вашему, нейросети принесут наибольшую пользу человечеству в ближайшие 10 лет? (Выберите не более 3-х вариантов) / Образование (персонализированное обучение) | AN1: В каких сферах, по-вашему, нейросети принесут наибольшую пользу человечеству в ближайшие 10 лет? (Выберите не более 3-х вариантов) / Наука и исследования | AO1: В каких сферах, по-вашему, нейросети принесут наибольшую пользу человечеству в ближайшие 10 лет? (Выберите не более 3-х вариантов) / Искусство и креативные индустрии | AP1: В каких сферах, по-вашему, нейросети принесут наибольшую пользу человечеству в ближайшие 10 лет? (Выберите не более 3-х вариантов) / Персональные ассистенты и бытовые задачи | AQ1: В каких сферах, по-вашему, нейросети принесут наибольшую пользу человечеству в ближайшие 10 лет? (Выберите не более 3-х вариантов) / Транспорт и логистика (беспилотные системы) | AR1: В каких сферах, по-вашему, нейросети принесут наибольшую пользу человечеству в ближайшие 10 лет? (Выберите не более 3-х вариантов) / Борьба с изменением климата | AS1: В каких сферах, по-вашему, нейросети принесут наибольшую пользу человечеству в ближайшие 10 лет? (Выберите не более 3-х вариантов) / Кибербезопасность | AT1: Как вы считаете, может ли музыка, картина или литературное произведение, созданные нейросетью, считаться искусством? | AU1: Должны ли нейросети иметь авторские права? | AV1: Представьте, что нейросеть достигла уровня, сравнимого с человеческим интеллектом (сильный ИИ). Какой из сценариев вам кажется наиболее вероятным? | AW1: Как вы относитесь к идее романтических или дружеских отношений между человеком и ИИ?
A2: 2208596649 | B2: 19-22 | C2: Студент (Колледж/Университет) | D2: Да | E2: Друзья/коллеги | F2: Да | G2: Ежедневно | H2: ChatGPT | I2: DeepSeek | Q2: Поиск информации, обучение | R2: Написание текстов | S2: Создание изображений, артов | U2: Программирование | Y2: 5 | Z2: Нет, мне хватает бесплатных | AA2: 3 | AB2: Буду использовать больше | AC2: Потеря работ | AE2: Потеря креативности | AI2: Трансформирует профессии | AJ2: 5 | AK2: 10 | AL2: Медицина (диагностика, разработка лекарств) | AN2: Наука и исследования | AQ2: Транспорт и логистика (беспилотные системы) | AT2: Нет, это лишь имитация и компиляция без души и замысла. | AU2: Нет | AV2: Симбиоз: Люди и ИИ будут тесно сотрудничать и усиливать друг друга. | AW2: Это патология и деградация человеческих отношений.
A3: 2208609765 | B3: 19-22 | C3: Студент (Колледж/Университет) | D3: Да | E3: Новости | F3: Да | G3: Ежедневно | H3: ChatGPT | I3: DeepSeek | Q3: Поиск информации, обучение | R3: Написание текстов | U3: Программирование | V3: Работа | Y3: 5 | Z3: Нет, мне хватает бесплатных | AA3: 4 | AB3: Буду использовать больше | AD3: Фейковая информация | AE3: Потеря креативности | AG3: Развитие лени | AI3: Трансформирует профессии | AJ3: 3 | AK3: 8 | AL3: Медицина (диагностика, разработка лекарств) | AM3: Образование (персонализированное обучение) | AN3: Наука и исследования | AP3: Персональные ассистенты и бытовые задачи | AQ3: Транспорт и логистика (беспилотные системы) | AT3: Нет, это лишь имитация и компиляция без души и замысла. | AU3: Нет | AV3: Симбиоз: Люди и ИИ будут тесно сотрудничать и усиливать друг друга. | AW3: Это печально, но неизбежно для некоторых людей.
A4: 2208672120 | B4: 19-22 | C4: Студент (Колледж/Университет) | D4: Да | E4: Друзья/коллеги | F4: Да | G4: Ежедневно | I4: DeepSeek | Q4: Поиск информации, обучение | W4: Развлечения | Y4: 4 | Z4: Нет, мне хватает бесплатных | AA4: 3 | AB4: Останусь на текущем уровне | AC4: Потеря работ | AI4: Трансформирует профессии | AJ4: 2 | AK4: 3 | AL4: Медицина (диагностика, разработка лекарств) | AM4: Образование (персонализированное обучение) | AT4: Да, безусловно. Главное — результат, а не создатель. | AU4: Затрудняюсь ответить | AV4: Симбиоз: Люди и ИИ будут тесно сотрудничать и усиливать друг друга. | AW4: Это печально, но неизбежно для некоторых людей.
A5: 2208695364 | B5: 17-18 | C5: Студент (Колледж/Университет) | D5: Да | E5: Друзья/коллеги | F5: Да | G5: Ежедневно | H5: ChatGPT | I5: DeepSeek | K5: YandexGPT | L5: GigaChat | Q5: Поиск информации, обучение | R5: Написание текстов | S5: Создание изображений, артов | T5: Создание видео | U5: Программирование | V5: Работа | W5: Развлечения | Y5: 5 | Z5: Да, уже плачу | AA5: 5 | AB5: Буду использовать больше | AC5: Потеря работ | AD5: Фейковая информация | AE5: Потеря креативности | AF5: Контроль над людьми | AG5: Развитие лени | AI5: Трансформирует профессии | AJ5: 3 | AK5: 7 | AL5: Медицина (диагностика, разработка лекарств) | AM5: Образование (персонализированное обучение) | AN5: Наука и исследования | AO5: Искусство и креативные индустрии | AP5: Персональные ассистенты и бытовые задачи | AQ5: Транспорт и логистика (беспилотные системы) | AR5: Борьба с изменением климата | AS5: Кибербезопасность | AT5: Да, безусловно. Главное — результат, а не создатель. | AU5: Да | AV5: Технологическая утопия: ИИ решит главные проблемы человечества (голод, болезни). | AW5: Это естественное развитие будущего, я бы попробовал(а).
A6: 2208979338 | B6: 19-22 | C6: Студент (Колледж/Университет) | D6: Да | E6: Личный опыт | F6: Да | G6: Ежедневно | H6: ChatGPT | I6: DeepSeek | Q6: Поиск информации, обучение | R6: Написание текстов | U6: Программирование | Y6: 3 | Z6: Нет, мне хватает бесплатных | AA6: 2 | AB6: Не знаю | AC6: Потеря работ | AD6: Фейковая информация | AE6: Потеря креативности | AI6: Трансформирует профессии | AJ6: 3 | AK6: 6 | AL6: Медицина (диагностика, разработка лекарств) | AM6: Образование (персонализированное обучение) | AP6: Персональные ассистенты и бытовые задачи | AQ6: Транспорт и логистика (беспилотные системы) | AT6: Да, но это другой, особый вид искусства. | AU6: Нет | AV6: Социальный коллапс: Массовая безработица и экономическое неравенство. | AW6: Это патология и деградация человеческих отношений.
A7: 2209297250 | B7: 19-22 | C7: Студент (Колледж/Университет) | D7: Да | E7: Личный опыт | F7: Да | G7: Ежедневно | H7: ChatGPT | I7: DeepSeek | J7: Grok | P7: Другие | Q7: Поиск информации, обучение | R7: Написание текстов | Y7: 3 | Z7: Нет, мне хватает бесплатных | AA7: 2 | AB7: Останусь на текущем уровне | AD7: Фейковая информация | AG7: Развитие лени | AI7: Создаёт больше профессий | AJ7: 5 | AK7: 7 | AM7: Образование (персонализированное обучение) | AP7: Персональные ассистенты и бытовые задачи | AQ7: Транспорт и логистика (беспилотные системы) | AT7: Нет, это лишь имитация и компиляция без души и замысла. | AU7: Да | AV7: Симбиоз: Люди и ИИ будут тесно сотрудничать и усиливать друг друга. | AW7: Это печально, но неизбежно для некоторых людей.
A8: 2213618385 | B8: 17-18 | C8: Студент (Колледж/Университет) | D8: Да | E8: Друзья/коллеги | F8: Да | G8: Ежедневно | I8: DeepSeek | P8: Другие | Q8: Поиск информации, обучение | R8: Написание текстов | U8: Программирование | Y8: 3 | Z8: Нет, мне хватает бесплатных | AA8: 3 | AB8: Не знаю | AD8: Фейковая информация | AG8: Развитие лени | AI8: Не повлияет значительно | AJ8: 3 | AK8: 6 | AL8: Медицина (диагностика, разработка лекарств) | AM8: Образование (персонализированное обучение) | AN8: Наука и исследования | AT8: Нет, это лишь имитация и компиляция без души и замысла. | AU8: Нет | AV8: Затрудняюсь ответить. | AW8: Это просто фантастика, которая никогда не станет реальностью.
A9: 2214108153 | B9: 19-22 | C9: Студент (Колледж/Университет) | D9: Да | E9: Друзья/коллеги | F9: Да | G9: Несколько раз в неделю | H9: ChatGPT | I9: DeepSeek | Q9: Поиск информации, обучение | R9: Написание текстов | Y9: 3 | Z9: Нет, мне хватает бесплатных | AA9: 2 | AB9: Буду использовать больше | AD9: Фейковая информация | AG9: Развитие лени | AI9: Трансформирует профессии | AJ9: 3 | AK9: 5 | AO9: Искусство и креативные индустрии | AP9: Персональные ассистенты и бытовые задачи | AS9: Кибербезопасность | AT9: Да, безусловно. Главное — результат, а не создатель. | AU9: Нет | AV9: Симбиоз: Люди и ИИ будут тесно сотрудничать и усиливать друг друга. | AW9: Это патология и деградация человеческих отношений.
A10: 2214108361 | B10: до 14 | C10: Студент (Колледж/Университет) | D10: Нет
A11: 2214108607 | B11: 19-22 | C11: Другая сфера деятельности | D11: Да | E11: Соцсети | F11: Да | G11: Редко | H11: ChatGPT | I11: DeepSeek | K11: YandexGPT | L11: GigaChat | Q11: Поиск информации, обучение | R11: Написание текстов | S11: Создание изображений, артов | W11: Развлечения | Y11: 5 | Z11: Нет, мне хватает бесплатных | AA11: 3 | AB11: Останусь на текущем уровне | AC11: Потеря работ | AD11: Фейковая информация | AE11: Потеря креативности | AG11: Развитие лени | AI11: Уничтожает больше профессий | AJ11: 4 | AK11: 6 | AO11: Искусство и креативные индустрии | AP11: Персональные ассистенты и бытовые задачи | AQ11: Транспорт и логистика (беспилотные системы) | AT11: Нет, это лишь имитация и компиляция без души и замысла. | AU11: Нет | AV11: Социальный коллапс: Массовая безработица и экономическое неравенство. | AW11: Это патология и деградация человеческих отношений.
A12: 2214110028 | B12: 19-22 | C12: Студент (Колледж/Университет) | D12: Да | E12: Соцсети | F12: Да | G12: Ежедневно | H12: ChatGPT | I12: DeepSeek | J12: Grok | K12: YandexGPT | L12: GigaChat | M12: Генераторы изображений (Midjourney, Kandinsky) | N12: Генераторы видео (Sora и др.) | O12: Нейросети для обработки фото/видео | P12: Другие | Q12: Поиск информации, обучение | R12: Написание текстов | S12: Создание изображений, артов | T12: Создание видео | U12: Программирование | V12: Работа | W12: Развлечения | X12: Пока не использую | Y12: 5 | Z12: Да, рассматриваю | AA12: 4 | AB12: Буду использовать больше | AH12: Рисков не вижу | AI12: Уничтожает больше профессий | AJ12: 5 | AK12: 10 | AL12: Медицина (диагностика, разработка лекарств) | AS12: Кибербезопасность | AT12: Да, безусловно. Главное — результат, а не создатель. | AU12: Нет | AV12: Технологическая утопия: ИИ решит главные проблемы человечества (голод, болезни). | AW12: Это патология и деградация человеческих отношений.
A13: 2214113592 | B13: 46+ | C13: IT-сфера | D13: Нет
A14: 2214113764 | B14: 19-22 | C14: Студент (Колледж/Университет) | D14: Да | E14: Соцсети | F14: Да | G14: Несколько раз в неделю | I14: DeepSeek | L14: GigaChat | Q14: Поиск информации, обучение | R14: Написание текстов | U14: Программирование | Y14: 4 | Z14: Нет, мне хватает бесплатных | AA14: 3 | AB14: Не знаю | AC14: Потеря работ | AD14: Фейковая информация | AE14: Потеря креативности | AG14: Развитие лени | AI14: Уничтожает больше профессий | AJ14: 2 | AK14: 3 | AL14: Медицина (диагностика, разработка лекарств) | AN14: Наука и исследования | AP14: Персональные ассистенты и бытовые задачи | AQ14: Транспорт и логистика (беспилотные системы) | AT14: Затрудняюсь ответить. | AU14: Затрудняюсь ответить | AV14: Социальный коллапс: Массовая безработица и экономическое неравенство. | AW14: Это патология и деградация человеческих отношений.
A15: 2214113979 | B15: 19-22 | C15: Студент (Колледж/Университет) | D15: Да | E15: Личный опыт | F15: Да | G15: Ежедневно | P15: Другие | Q15: Поиск информации, обучение | R15: Написание текстов | Y15: 5 | Z15: Нет, я против платы за это | AA15: 3 | AB15: Не знаю | AE15: Потеря креативности | AG15: Развитие лени | AI15: Не повлияет значительно | AJ15: 3 | AK15: 7 | AL15: Медицина (диагностика, разработка лекарств) | AN15: Наука и исследования | AP15: Персональные ассистенты и бытовые задачи | AQ15: Транспорт и логистика (беспилотные системы) | AT15: Да, но это другой, особый вид искусства. | AU15: Затрудняюсь ответить | AV15: Технологическая утопия: ИИ решит главные проблемы человечества (голод, болезни). | AW15: Это патология и деградация человеческих отношений.
A16: 2214126918 | B16: 17-18 | C16: Школьник | D16: Да | E16: Соцсети | F16: Да | G16: Несколько раз в неделю | H16: ChatGPT | I16: DeepSeek | O16: Нейросети для обработки фото/видео | Q16: Поиск информации, обучение | R16: Написание текстов | S16: Создание изображений, артов | T16: Создание видео | W16: Развлечения | Y16: 2 | Z16: Нет, мне хватает бесплатных | AA16: 3 | AB16: Останусь на текущем уровне | AC16: Потеря работ | AD16: Фейковая информация | AE16: Потеря креативности | AF16: Контроль над людьми | AG16: Развитие лени | AI16: Создаёт больше профессий | AJ16: 3 | AK16: 5 | AL16: Медицина (диагностика, разработка лекарств) | AM16: Образование (персонализированное обучение) | AN16: Наука и исследования | AO16: Искусство и креативные индустрии | AP16: Персональные ассистенты и бытовые задачи | AQ16: Транспорт и логистика (беспилотные системы) | AS16: Кибербезопасность | AT16: Нет, это лишь имитация и компиляция без души и замысла. | AU16: Нет | AV16: Социальный коллапс: Массовая безработица и экономическое неравенство. | AW16: Это печально, но неизбежно для некоторых людей.
A17: 2214132085 | B17: 19-22 | C17: Студент (Колледж/Университет) | D17: Да | E17: Соцсети | F17: Да | G17: Несколько раз в неделю | H17: ChatGPT | I17: DeepSeek | Q17: Поиск информации, обучение | R17: Написание текстов | U17: Программирование | V17: Работа | Y17: 4 | Z17: Нет, мне хватает бесплатных | AA17: 3 | AB17: Буду использовать больше | AD17: Фейковая информация | AG17: Развитие лени | AI17: Не повлияет значительно | AJ17: 4 | AK17: 7 | AO17: Искусство и креативные индустрии | AQ17: Транспорт и логистика (беспилотные системы) | AS17: Кибербезопасность | AT17: Нет, это лишь имитация и компиляция без души и замысла. | AU17: Затрудняюсь ответить | AV17: Затрудняюсь ответить. | AW17: Это патология и деградация человеческих отношений.
A18: 2214157635 | B18: 19-22 | C18: Студент (Колледж/Университет) | D18: Да | E18: Соцсети | F18: Да | G18: Несколько раз в неделю | H18: ChatGPT | I18: DeepSeek | K18: YandexGPT | M18: Генераторы изображений (Midjourney, Kandinsky) | Q18: Поиск информации, обучение | R18: Написание текстов | S18: Создание изображений, артов | U18: Программирование | V18: Работа | W18: Развлечения | Y18: 5 | Z18: Да, рассматриваю | AA18: 4 | AB18: Останусь на текущем уровне | AC18: Потеря работ | AE18: Потеря креативности | AG18: Развитие лени | AI18: Трансформирует профессии | AJ18: 4 | AK18: 9 | AN18: Наука и исследования | AQ18: Транспорт и логистика (беспилотные системы) | AS18: Кибербезопасность | AT18: Нет, это лишь имитация и компиляция без души и замысла. | AU18: Нет | AV18: Технологическая утопия: ИИ решит главные проблемы человечества (голод, болезни). | AW18: Это патология и деградация человеческих отношений.
A19: 2214188077 | B19: 17-18 | C19: Студент (Колледж/Университет) | D19: Да | E19: Личный опыт | F19: Да | G19: Ежедневно | H19: ChatGPT | I19: DeepSeek | L19: GigaChat | M19: Генераторы изображений (Midjourney, Kandinsky) | O19: Нейросети для обработки фото/видео | Q19: Поиск информации, обучение | R19: Написание текстов | S19: Создание изображений, артов | U19: Программирование | W19: Развлечения | Y19: 5 | Z19: Да, рассматриваю | AA19: 4 | AB19: Буду использовать больше | AD19: Фейковая информация | AG19: Развитие лени | AI19: Не повлияет значительно | AJ19: 5 | AK19: 8 | AM19: Образование (персонализированное обучение) | AP19: Персональные ассистенты и бытовые задачи | AS19: Кибербезопасность | AT19: Нет, это лишь имитация и компиляция без души и замысла. | AU19: Да | AV19: Симбиоз: Люди и ИИ будут тесно сотрудничать и усиливать друг друга. | AW19: Это просто фантастика, которая никогда не станет реальностью.
A20: 2214193525 | B20: 19-22 | C20: Студент (Колледж/Университет) | D20: Да | E20: Друзья/коллеги | F20: Да | G20: Ежедневно | H20: ChatGPT | I20: DeepSeek | Q20: Поиск информации, обучение | R20: Написание текстов | V20: Работа | Y20: 5 | Z20: Да, рассматриваю | AA20: 3 | AB20: Останусь на текущем уровне | AC20: Потеря работ | AD20: Фейковая информация | AG20: Развитие лени | AI20: Трансформирует профессии | AJ20: 4 | AK20: 6 | AM20: Образование (персонализированное обучение) | AO20: Искусство и креативные индустрии | AP20: Персональные ассистенты и бытовые задачи | AS20: Кибербезопасность | AT20: Нет, это лишь имитация и компиляция без души и замысла. | AU20: Затрудняюсь ответить | AV20: Симбиоз: Люди и ИИ будут тесно сотрудничать и усиливать друг друга. | AW20: Это печально, но неизбежно для некоторых людей.
A21: 2214195903 | B21: 17-18 | C21: Студент (Колледж/Университет) | D21: Да | E21: Личный опыт | F21: Да | G21: Несколько раз в неделю | H21: ChatGPT | Q21: Поиск информации, обучение | Y21: 4 | Z21: Нет, мне хватает бесплатных | AA21: 3 | AB21: Буду использовать больше | AD21: Фейковая информация | AE21: Потеря креативности | AG21: Развитие лени | AI21: Трансформирует профессии | AJ21: 4 | AK21: 5 | AO21: Искусство и креативные индустрии | AP21: Персональные ассистенты и бытовые задачи | AS21: Кибербезопасность | AT21: Да, но это другой, особый вид искусства. | AU21: Да | AV21: Симбиоз: Люди и ИИ будут тесно сотрудничать и усиливать друг друга. | AW21: Это патология и деградация человеческих отношений.
A22: 2214235916 | B22: 19-22 | C22: Студент (Колледж/Университет) | D22: Да | E22: Соцсети | F22: Да | G22: Несколько раз в неделю | H22: ChatGPT | I22: DeepSeek | Q22: Поиск информации, обучение | R22: Написание текстов | Y22: 4 | Z22: Нет, мне хватает бесплатных | AA22: 3 | AB22: Останусь на текущем уровне | AE22: Потеря креативности | AG22: Развитие лени | AI22: Трансформирует профессии | AJ22: 4 | AK22: 6 | AL22: Медицина (диагностика, разработка лекарств) | AM22: Образование (персонализированное обучение) | AN22: Наука и исследования | AQ22: Транспорт и логистика (беспилотные системы) | AS22: Кибербезопасность | AT22: Нет, это лишь имитация и компиляция без души и замысла. | AU22: Затрудняюсь ответить | AV22: Симбиоз: Люди и ИИ будут тесно сотрудничать и усиливать друг друга. | AW22: Это просто фантастика, которая никогда не станет реальностью.
A23: 2214257205 | B23: 17-18 | C23: Студент (Колледж/Университет) | D23: Да | E23: Соцсети | F23: Да | G23: Ежедневно | H23: ChatGPT | I23: DeepSeek | K23: YandexGPT | O23: Нейросети для обработки фото/видео | Q23: Поиск информации, обучение | R23: Написание текстов | Y23: 5 | Z23: Нет, мне хватает бесплатных | AA23: 3 | AB23: Останусь на текущем уровне | AC23: Потеря работ | AI23: Не повлияет значительно | AJ23: 4 | AK23: 9 | AL23: Медицина (диагностика, разработка лекарств) | AM23: Образование (персонализированное обучение) | AN23: Наука и исследования | AP23: Персональные ассистенты и бытовые задачи | AQ23: Транспорт и логистика (беспилотные системы) | AS23: Кибербезопасность | AT23: Да, но это другой, особый вид искусства. | AU23: Затрудняюсь ответить | AV23: Симбиоз: Люди и ИИ будут тесно сотрудничать и усиливать друг друга. | AW23: Это печально, но неизбежно для некоторых людей.
A24: 2214266629 | B24: 19-22 | C24: Студент (Колледж/Университет) | D24: Да | E24: Друзья/коллеги | F24: Да | G24: Ежедневно | H24: ChatGPT | I24: DeepSeek | Q24: Поиск информации, обучение | S24: Создание изображений, артов | U24: Программирование | Y24: 5 | Z24: Нет, мне хватает бесплатных | AA24: 4 | AB24: Останусь на текущем уровне | AD24: Фейковая информация | AI24: Уничтожает больше профессий | AJ24: 5 | AK24: 8 | AL24: Медицина (диагностика, разработка лекарств) | AM24: Образование (персонализированное обучение) | AQ24: Транспорт и логистика (беспилотные системы) | AT24: Да, безусловно. Главное — результат, а не создатель. | AU24: Нет | AV24: Симбиоз: Люди и ИИ будут тесно сотрудничать и усиливать друг друга. | AW24: Это естественное развитие будущего, я бы попробовал(а).
A25: 2214288577 | B25: 19-22 | C25: IT-сфера | D25: Да | E25: Курсы/учеба | F25: Да | G25: Ежедневно | H25: ChatGPT | I25: DeepSeek | J25: Grok | K25: YandexGPT | L25: GigaChat | M25: Генераторы изображений (Midjourney, Kandinsky) | N25: Генераторы видео (Sora и др.) | O25: Нейросети для обработки фото/видео | P25: Другие | Q25: Поиск информации, обучение | R25: Написание текстов | S25: Создание изображений, артов | T25: Создание видео | U25: Программирование | V25: Работа | W25: Развлечения | Y25: 4 | Z25: Да, рассматриваю | AA25: 2 | AB25: Буду использовать больше | AD25: Фейковая информация | AE25: Потеря креативности | AG25: Развитие лени | AI25: Трансформирует профессии | AJ25: 5 | AK25: 10 | AL25: Медицина (диагностика, разработка лекарств) | AM25: Образование (персонализированное обучение) | AN25: Наука и исследования | AP25: Персональные ассистенты и бытовые задачи | AQ25: Транспорт и логистика (беспилотные системы) | AT25: Нет, это лишь имитация и компиляция без души и замысла. | AU25: Нет | AV25: Симбиоз: Люди и ИИ будут тесно сотрудничать и усиливать друг друга. | AW25: Это естественное развитие будущего, я бы попробовал(а).
A26: 2214478051 | B26: 19-22 | C26: Другая сфера деятельности | D26: Да | E26: Друзья/коллеги | F26: Нет | AD26: Фейковая информация | AG26: Развитие лени | AI26: Не повлияет значительно | AJ26: 1 | AK26: 3 | AL26: Медицина (диагностика, разработка лекарств) | AM26: Образование (персонализированное обучение) | AP26: Персональные ассистенты и бытовые задачи | AQ26: Транспорт и логистика (беспилотные системы) | AT26: Нет, это лишь имитация и компиляция без души и замысла. | AU26: Нет | AV26: Симбиоз: Люди и ИИ будут тесно сотрудничать и усиливать друг друга. | AW26: Это патология и деградация человеческих отношений.
A27: 2214570620 | B27: 19-22 | C27: Студент (Колледж/Университет) | D27: Да | E27: Друзья/коллеги | F27: Да | G27: Ежедневно | H27: ChatGPT | I27: DeepSeek | Q27: Поиск информации, обучение | R27: Написание текстов | U27: Программирование | V27: Работа | Y27: 5 | Z27: Да, рассматриваю | AA27: 4 | AB27: Буду использовать больше | AE27: Потеря креативности | AG27: Развитие лени | AI27: Трансформирует профессии | AJ27: 4 | AK27: 5 | AL27: Медицина (диагностика, разработка лекарств) | AM27: Образование (персонализированное обучение) | AN27: Наука и исследования | AP27: Персональные ассистенты и бытовые задачи | AT27: Нет, это лишь имитация и компиляция без души и замысла. | AU27: Затрудняюсь ответить | AV27: Технологическая утопия: ИИ решит главные проблемы человечества (голод, болезни). | AW27: Это печально, но неизбежно для некоторых людей.
A28: 2214649464 | B28: 46+ | C28: Школьник | D28: Да | E28: Личный опыт | F28: Да | G28: Ежедневно | H28: ChatGPT | I28: DeepSeek | J28: Grok | K28: YandexGPT | L28: GigaChat | M28: Генераторы изображений (Midjourney, Kandinsky) | N28: Генераторы видео (Sora и др.) | O28: Нейросети для обработки фото/видео | P28: Другие | Q28: Поиск информации, обучение | R28: Написание текстов | S28: Создание изображений, артов | T28: Создание видео | U28: Программирование | V28: Работа | W28: Развлечения | X28: Пока не использую | Y28: 5 | Z28: Нет, я против платы за это | AA28: 5 | AB28: Буду использовать меньше | AC28: Потеря работ | AD28: Фейковая информация | AE28: Потеря креативности | AF28: Контроль над людьми | AG28: Развитие лени | AH28: Рисков не вижу | AI28: Трансформирует профессии | AJ28: 5 | AK28: 8 | AL28: Медицина (диагностика, разработка лекарств) | AM28: Образование (персонализированное обучение) | AN28: Наука и исследования | AP28: Персональные ассистенты и бытовые задачи | AQ28: Транспорт и логистика (беспилотные системы) | AR28: Борьба с изменением климата | AS28: Кибербезопасность | AT28: Нет, это лишь имитация и компиляция без души и замысла. | AU28: Нет | AV28: Потеря контроля: ИИ станет настолько могущественным, что мы не сможем им управлять. | AW28: Это естественное развитие будущего, я бы попробовал(а).
A29: 2214704556 | B29: 19-22 | C29: Студент (Колледж/Университет) | D29: Да | E29: Личный опыт | F29: Да | G29: Несколько раз в неделю | I29: DeepSeek | Q29: Поиск информации, обучение | R29: Написание текстов | U29: Программирование | Y29: 4 | Z29: Нет, мне хватает бесплатных | AA29: 3 | AB29: Буду использовать больше | AD29: Фейковая информация | AE29: Потеря креативности | AG29: Развитие лени | AI29: Трансформирует профессии | AJ29: 4 | AK29: 7 | AL29: Медицина (диагностика, разработка лекарств) | AM29: Образование (персонализированное обучение) | AN29: Наука и исследования | AO29: Искусство и креативные индустрии | AP29: Персональные ассистенты и бытовые задачи | AQ29: Транспорт и логистика (беспилотные системы) | AT29: Да, но это другой, особый вид искусства. | AU29: Нет | AV29: Симбиоз: Люди и ИИ будут тесно сотрудничать и усиливать друг друга. | AW29: Это печально, но неизбежно для некоторых людей.
A30: 2215058867 | B30: 19-22 | C30: Студент (Колледж/Университет) | D30: Да | E30: Соцсети | F30: Да | G30: Несколько раз в неделю | H30: ChatGPT | K30: YandexGPT | L30: GigaChat | Q30: Поиск информации, обучение | R30: Написание текстов | S30: Создание изображений, артов | Y30: 3 | Z30: Нет, мне хватает бесплатных | AA30: 3 | AB30: Буду использовать меньше | AD30: Фейковая информация | AE30: Потеря креативности | AG30: Развитие лени | AI30: Уничтожает больше профессий | AJ30: 5 | AK30: 5 | AO30: Искусство и креативные индустрии | AT30: Нет, это лишь имитация и компиляция без души и замысла. | AU30: Нет | AV30: Социальный коллапс: Массовая безработица и экономическое неравенство. | AW30: Это патология и деградация человеческих отношений.
A31: 2215262846 | B31: 19-22 | C31: Студент (Колледж/Университет) | D31: Да | E31: Личный опыт | F31: Да | G31: Ежедневно | H31: ChatGPT | I31: DeepSeek | Q31: Поиск информации, обучение | R31: Написание текстов | U31: Программирование | Y31: 5 | Z31: Нет, мне хватает бесплатных | AA31: 3 | AB31: Буду использовать больше | AC31: Потеря работ | AD31: Фейковая информация | AE31: Потеря креативности | AG31: Развитие лени | AI31: Трансформирует профессии | AJ31: 4 | AK31: 9 | AM31: Образование (персонализированное обучение) | AN31: Наука и исследования | AO31: Искусство и креативные индустрии | AP31: Персональные ассистенты и бытовые задачи | AT31: Да, но это другой, особый вид искусства. | AU31: Нет | AV31: Затрудняюсь ответить. | AW31: Это просто фантастика, которая никогда не станет реальностью.
A32: 2219943466 | B32: 19-22 | C32: Студент (Колледж/Университет) | D32: Да | E32: Новости | F32: Да | G32: Ежедневно | I32: DeepSeek | J32: Grok | Q32: Поиск информации, обучение | R32: Написание текстов | U32: Программирование | V32: Работа | Y32: 2 | Z32: Нет, мне хватает бесплатных | AA32: 3 | AB32: Буду использовать меньше | AD32: Фейковая информация | AE32: Потеря креативности | AG32: Развитие лени | AI32: Не повлияет значительно | AJ32: 4 | AK32: 6 | AP32: Персональные ассистенты и бытовые задачи | AT32: Нет, это лишь имитация и компиляция без души и замысла. | AU32: Нет | AV32: Симбиоз: Люди и ИИ будут тесно сотрудничать и усиливать друг друга. | AW32: Это патология и деградация человеческих отношений.
A33: 2222538236 | B33: 19-22 | C33: Студент (Колледж/Университет) | D33: Да | E33: Соцсети | F33: Да | G33: Несколько раз в неделю | H33: ChatGPT | I33: DeepSeek | Q33: Поиск информации, обучение | R33: Написание текстов | W33: Развлечения | Y33: 4 | Z33: Нет, мне хватает бесплатных | AA33: 3 | AB33: Останусь на текущем уровне | AC33: Потеря работ | AD33: Фейковая информация | AE33: Потеря креативности | AG33: Развитие лени | AI33: Уничтожает больше профессий | AJ33: 4 | AK33: 4 | AL33: Медицина (диагностика, разработка лекарств) | AP33: Персональные ассистенты и бытовые задачи | AT33: Нет, это лишь имитация и компиляция без души и замысла. | AU33: Затрудняюсь ответить | AV33: Социальный коллапс: Массовая безработица и экономическое неравенство. | AW33: Это печально, но неизбежно для некоторых людей.
A34: 2223547405 | B34: 19-22 | C34: Студент (Колледж/Университет) | D34: Да | E34: Друзья/коллеги | F34: Да | G34: Несколько раз в неделю | H34: ChatGPT | I34: DeepSeek | J34: Grok | Q34: Поиск информации, обучение | R34: Написание текстов | U34: Программирование | Y34: 5 | Z34: Да, рассматриваю | AA34: 4 | AB34: Останусь на текущем уровне | AE34: Потеря креативности | AG34: Развитие лени | AI34: Трансформирует профессии | AJ34: 5 | AK34: 6 | AL34: Медицина (диагностика, разработка лекарств) | AM34: Образование (персонализированное обучение) | AN34: Наука и исследования | AQ34: Транспорт и логистика (беспилотные системы) | AT34: Нет, это лишь имитация и компиляция без души и замысла. | AU34: Затрудняюсь ответить | AV34: Технологическая утопия: ИИ решит главные проблемы человечества (голод, болезни). | AW34: Это патология и деградация человеческих отношений.
A35: 2225468285 | B35: 23-30 | C35: Другая сфера деятельности | D35: Да | E35: Соцсети | F35: Да | G35: Редко | H35: ChatGPT | I35: DeepSeek | Q35: Поиск информации, обучение | Y35: 5 | Z35: Да, рассматриваю | AA35: 4 | AB35: Буду использовать больше | AE35: Потеря креативности | AF35: Контроль над людьми | AG35: Развитие лени | AI35: Уничтожает больше профессий | AJ35: 5 | AK35: 7 | AN35: Наука и исследования | AP35: Персональные ассистенты и бытовые задачи | AS35: Кибербезопасность | AT35: Нет, это лишь имитация и компиляция без души и замысла. | AU35: Затрудняюсь ответить | AV35: Социальный коллапс: Массовая безработица и экономическое неравенство. | AW35: Это печально, но неизбежно для некоторых людей.
A36: 2225474264 | B36: 19-22 | C36: Другая сфера деятельности | D36: Да | E36: Соцсети | F36: Да | G36: Редко | O36: Нейросети для обработки фото/видео | P36: Другие | W36: Развлечения | X36: Пока не использую | Y36: 3 | Z36: Нет, мне хватает бесплатных | AA36: 4 | AB36: Не знаю | AE36: Потеря креативности | AI36: Не повлияет значительно | AJ36: 4 | AK36: 8 | AL36: Медицина (диагностика, разработка лекарств) | AN36: Наука и исследования | AO36: Искусство и креативные индустрии | AP36: Персональные ассистенты и бытовые задачи | AS36: Кибербезопасность | AT36: Да, но это другой, особый вид искусства. | AU36: Да | AV36: Симбиоз: Люди и ИИ будут тесно сотрудничать и усиливать друг друга. | AW36: Это печально, но неизбежно для некоторых людей.
A37: 2225476174 | B37: 23-30 | C37: IT-сфера | D37: Да | E37: Курсы/учеба | F37: Да | G37: Ежедневно | H37: ChatGPT | I37: DeepSeek | K37: YandexGPT | M37: Генераторы изображений (Midjourney, Kandinsky) | Q37: Поиск информации, обучение | R37: Написание текстов | U37: Программирование | V37: Работа | Y37: 5 | Z37: Да, рассматриваю | AA37: 4 | AB37: Буду использовать больше | AC37: Потеря работ | AD37: Фейковая информация | AE37: Потеря креативности | AG37: Развитие лени | AI37: Трансформирует профессии | AJ37: 5 | AK37: 3 | AL37: Медицина (диагностика, разработка лекарств) | AM37: Образование (персонализированное обучение) | AN37: Наука и исследования | AO37: Искусство и креативные индустрии | AP37: Персональные ассистенты и бытовые задачи | AQ37: Транспорт и логистика (беспилотные системы) | AT37: Нет, это лишь имитация и компиляция без души и замысла. | AU37: Затрудняюсь ответить | AV37: Технологическая утопия: ИИ решит главные проблемы человечества (голод, болезни). | AW37: Это естественное развитие будущего, я бы попробовал(а).
A38: 2225479548 | B38: 19-22 | C38: Не работаю / В поиске | D38: Да | E38: Друзья/коллеги | F38: Да | G38: Ежедневно | H38: ChatGPT | I38: DeepSeek | Q38: Поиск информации, обучение | R38: Написание текстов | S38: Создание изображений, артов | T38: Создание видео | Y38: 5 | Z38: Да, рассматриваю | AA38: 4 | AB38: Буду использовать больше | AC38: Потеря работ | AE38: Потеря креативности | AI38: Трансформирует профессии | AJ38: 5 | AK38: 10 | AM38: Образование (персонализированное обучение) | AO38: Искусство и креативные индустрии | AT38: Да, безусловно. Главное — результат, а не создатель. | AU38: Нет | AV38: Симбиоз: Люди и ИИ будут тесно сотрудничать и усиливать друг друга. | AW38: Это естественное развитие будущего, я бы попробовал(а).
A39: 2225486182 | B39: 19-22 | C39: Студент (Колледж/Университет) | D39: Да | E39: Личный опыт | F39: Да | G39: Ежедневно | H39: ChatGPT | I39: DeepSeek | K39: YandexGPT | P39: Другие | Q39: Поиск информации, обучение | R39: Написание текстов | U39: Программирование | V39: Работа | Y39: 3 | Z39: Да, рассматриваю | AA39: 4 | AB39: Останусь на текущем уровне | AD39: Фейковая информация | AE39: Потеря креативности | AI39: Трансформирует профессии | AJ39: 4 | AK39: 7 | AM39: Образование (персонализированное обучение) | AP39: Персональные ассистенты и бытовые задачи | AS39: Кибербезопасность | AT39: Затрудняюсь ответить. | AU39: Затрудняюсь ответить | AV39: Социальный коллапс: Массовая безработица и экономическое неравенство. | AW39: Это патология и деградация человеческих отношений.
A40: 2225492337 | B40: 19-22 | C40: IT-сфера | D40: Да | E40: Курсы/учеба | F40: Да | G40: Ежедневно | H40: ChatGPT | I40: DeepSeek | M40: Генераторы изображений (Midjourney, Kandinsky) | N40: Генераторы видео (Sora и др.) | Q40: Поиск информации, обучение | R40: Написание текстов | S40: Создание изображений, артов | U40: Программирование | V40: Работа | Y40: 4 | Z40: Да, рассматриваю | AA40: 1 | AB40: Буду использовать больше | AC40: Потеря работ | AD40: Фейковая информация | AE40: Потеря креативности | AI40: Трансформирует профессии | AJ40: 5 | AK40: 5 | AL40: Медицина (диагностика, разработка лекарств) | AM40: Образование (персонализированное обучение) | AN40: Наука и исследования | AS40: Кибербезопасность | AT40: Да, но это другой, особый вид искусства. | AU40: Нет | AV40: Симбиоз: Люди и ИИ будут тесно сотрудничать и усиливать друг друга. | AW40: Это естественное развитие будущего, я бы попробовал(а).
...

Sheet Для шкал
A1: Как часто вы пользуетесь нейросетями? | B1: Как вы считаете, как нейросети влияют на вашу эффективность? / | C1: Насколько вы доверяете информации нейросетей? / 1-5 | D1: Насколько вы готовы осваивать новые навыки в связи с развитием ИИ? / 1-5 | E1: Насколько вы в целом оптимистично или пессимистично относитесь к стремительному развитию искусственного интеллекта? / 1 (Чрезвычайно пессимистично) — 10 (Чрезвычайно оптимистично).
A2: Ежедневно | B2: 5 | C2: 3 | D2: 5 | E2: 10
A3: Ежедневно | B3: 5 | C3: 4 | D3: 3 | E3: 8
A4: Ежедневно | B4: 4 | C4: 3 | D4: 2 | E4: 3
A5: Ежедневно | B5: 5 | C5: 5 | D5: 3 | E5: 7
A6: Ежедневно | B6: 3 | C6: 2 | D6: 3 | E6: 6
A7: Ежедневно | B7: 3 | C7: 2 | D7: 5 | E7: 7
A8: Ежедневно | B8: 3 | C8: 3 | D8: 3 | E8: 6
A9: Несколько раз в неделю | B9: 3 | C9: 2 | D9: 3 | E9: 5
A10: Редко | B10: 5 | C10: 3 | D10: 4 | E10: 6
A11: Ежедневно | B11: 5 | C11: 4 | D11: 5 | E11: 10
A12: Несколько раз в неделю | B12: 4 | C12: 3 | D12: 2 | E12: 3
A13: Ежедневно | B13: 5 | C13: 3 | D13: 3 | E13: 7
... A42: Ежедневно | B42: 4 | C42: 4 | D42: 3 | E42: 8
D43: 5 | E43: 8

Sheet Люди
A1: Возраст | B1: Выбор | D1: Сфера деятельности | G1: Выбор
A2: 19-22 | B2: =COUNTIF(первоначальная!B:B,A2) -> 30 | D2: Студент (Колледж/Университет) | G2: =COUNTIF(первоначальная!C:C,D2) -> 30
A3: 17-18 | B3: =COUNTIF(первоначальная!B:B,A3) -> 8 | D3: Другая сфера деятельности | G3: =COUNTIF(первоначальная!C:C,D3) -> 5
A4: 23-30 | B4: =COUNTIF(первоначальная!B:B,A4) -> 3 | D4: IT-сфера | G4: =COUNTIF(первоначальная!C:C,D4) -> 4
A5: 46+ | B5: =COUNTIF(первоначальная!B:B,A5) -> 2 | D5: Школьник | G5: =COUNTIF(первоначальная!C:C,D5) -> 4
A6: до 14 | B6: =COUNTIF(первоначальная!B:B,A6) -> 1 | D6: Не работаю / В поиске | G6: =COUNTIF(первоначальная!C:C,D6) -> 1

Sheet Популярная нейросеть 
A1: Какими нейросетями пользуются люди? | G1: Выбор
A2: Grok | G2: =COUNTIF(первоначальная!J:J,A2) -> 6
A3: YandexGPT | G3: =COUNTIF(первоначальная!K:K,A3) -> 12
A4: GigaChat | G4: =COUNTIF(первоначальная!L:L,A4) -> 9
A5: Генераторы изображений (Midjourney, Kandinsky) | G5: =COUNTIF(первоначальная!M:M,A5) -> 8
A6: Генераторы видео (Sora и др.) | G6: =COUNTIF(первоначальная!N:N,A6) -> 5
A7: Нейросети для обработки фото/видео | G7: =COUNTIF(первоначальная!O:O,A7) -> 7
A8: ChatGPT | G8: =COUNTIF(первоначальная!H:H,"ChatGPT") -> 34
A9: DeepSeek | G9: =COUNTIF(первоначальная!I:I,"DeepSeek") -> 35

Sheet Для каких задач
A1: Задачи | E1: Выбор
A2: Поиск информации, обучение | E2: =COUNTIF(первоначальная!Q:Q,A2) -> 40
A3: Написание текстов | E3: =COUNTIF(первоначальная!R:R,A3) -> 34
A4: Создание изображений, артов | E4: =COUNTIF(первоначальная!S:S,A4) -> 14
A5: Программирование | E5: =COUNTIF(первоначальная!U:U,A5) -> 22
A6: Работа | E6: =COUNTIF(первоначальная!V:V,A6) -> 14
A7: Развлечения | E7: =COUNTIF(первоначальная!W:W,A7) -> 12

Sheet Шкалы
A1: Шкала | B1: Среднее | C1: Медиана
A2: Эфективность (1-5) | B2: =AVERAGE('Для шкал'!B:B) -> 4.1707317 | C2: =MEDIAN('Для шкал'!B:B) -> 4
A3: Доверие (1-5) | B3: =AVERAGE('Для шкал'!C:C) -> 3.2926829 | C3: =MEDIAN('Для шкал'!C:C) -> 3
A4: Новые навыки (1-5) | B4: =AVERAGE('Для шкал'!D:D) -> 3.9285714 | C4: =MEDIAN('Для шкал'!D:D) -> 4
A5: Отношение к развитию (1-10) | B5: =AVERAGE('Для шкал'!E:E) -> 6.7142857 | C5: =MEDIAN('Для шкал'!E:E) -> 7

Sheet Сводная по частоте
A1: Как часто пользуются | B1: Эффективность | C1: Доверие | D1: Развитие навыков | E1: Отношение к развитию нейросетей
A2: Ежедневно | B2: =AVERAGEIF('Для шкал'!$A:$A,$A$2,'Для шкал'!B:B) -> 4.4 | C2: =AVERAGEIF('Для шкал'!$A:$A,A2,'Для шкал'!C:C) -> 3.28 | D2: =AVERAGEIF('Для шкал'!$A:$A,A2,'Для шкал'!D:D) -> 3.88 | E2: =AVERAGEIF('Для шкал'!$A:$A,A2,'Для шкал'!E:E) -> 7.2
A3: Несколько раз в неделю | B3: =AVERAGEIF('Для шкал'!A:A,A3,'Для шкал'!B:B) -> 3.6923077 | C3: =AVERAGEIF('Для шкал'!$A:$A,A3,'Для шкал'!C:C) -> 3.2307692 | D3: =AVERAGEIF('Для шкал'!$A:$A,A3,'Для шкал'!D:D) -> 3.7692308 | E3: =AVERAGEIF('Для шкал'!$A:$A,A3,'Для шкал'!E:E) -> 5.7692308
A4: Редко | B4: =AVERAGEIF('Для шкал'!A:A,A4,'Для шкал'!B:B) -> 4.3333333 | C4: =AVERAGEIF('Для шкал'!$A:$A,A4,'Для шкал'!C:C) -> 3.6666667 | D4: =AVERAGEIF('Для шкал'!$A:$A,A4,'Для шкал'!D:D) -> 4.6666667 | E4: =AVERAGEIF('Для шкал'!$A:$A,A4,'Для шкал'!E:E) -> 6.3333333
